<?xml version="1.0" ?>
<!-- =================================================================================== -->
<!-- |    This document was autogenerated by xacro from myfirst.urdf.xacro             | -->
<!-- |    EDITING THIS FILE BY HAND IS NOT RECOMMENDED                                 | -->
<!-- =================================================================================== -->
<robot name="myfirst">
  <!-- base -->
  <link name="base_link">
    <visual>
      <geometry>
        <cylinder length="0.6" radius="0.1"/>
      </geometry>
      <origin rpy="0 0 0" xyz="0 0 0.3"/>
    </visual>
    <collision>
      <geometry>
        <cylinder length="0.6" radius="0.1"/>
      </geometry>
      <origin rpy="0 0 0" xyz="0 0 0.3"/>
    </collision>
    <inertial>
      <origin rpy="0 0 0" xyz="0 0 0.3"/>
      <mass value="0.5"/>
      <inertia ixx="0.013" ixy="0" ixz="0" iyy="0.013" iyz="0" izz="0.005"/>
    </inertial>
  </link>
  <!-- link 1 -->
  <link name="link1">
    <visual>
      <geometry>
        <cylinder length="0.3" radius="0.2"/>
      </geometry>
      <origin rpy="0 0 0" xyz="0 0 0.15"/>
    </visual>
    <collision>
      <geometry>
        <cylinder length="0.3" radius="0.2"/>
      </geometry>
      <origin rpy="0 0 0" xyz="0 0 0.15"/>
    </collision>
    <inertial>
      <origin rpy="0 0 0" xyz="0 0 0.15"/>
      <mass value="0.4"/>
      <inertia ixx="0.008" ixy="0" ixz="0" iyy="0.008" iyz="0" izz="0.003"/>
    </inertial>
  </link>
  <!-- link 2 -->
  <link name="link2">
    <visual>
      <geometry>
        <cylinder length="0.6" radius="0.1"/>
      </geometry>
      <origin rpy="0 0 0" xyz="0 0 0.3"/>
    </visual>
    <collision>
      <geometry>
        <cylinder length="0.6" radius="0.1"/>
      </geometry>
      <origin rpy="0 0 0" xyz="0 0 0.3"/>
    </collision>
    <inertial>
      <origin rpy="0 0 0" xyz="0 0 0.3"/>
      <mass value="0.6"/>
      <inertia ixx="0.020" ixy="0" ixz="0" iyy="0.020" iyz="0" izz="0.006"/>
    </inertial>
  </link>
  <!-- link 3 -->
  <link name="link3">
    <visual>
      <geometry>
        <cylinder length="0.6" radius="0.1"/>
      </geometry>
      <origin rpy="0 0 0" xyz="0 0 0.3"/>
    </visual>
    <collision>
      <geometry>
        <cylinder length="0.6" radius="0.1"/>
      </geometry>
      <origin rpy="0 0 0" xyz="0 0 0.3"/>
    </collision>
    <inertial>
      <origin rpy="0 0 0" xyz="0 0 0.3"/>
      <mass value="0.6"/>
      <inertia ixx="0.020" ixy="0" ixz="0" iyy="0.020" iyz="0" izz="0.006"/>
    </inertial>
  </link>
  <!-- GRIPPER -->
  <link name="gripper_base">
    <visual>
      <geometry>
        <box size="0.1 0.1 0.1"/>
      </geometry>
    </visual>
    <collision>
      <geometry>
        <box size="0.1 0.1 0.1"/>
      </geometry>
    </collision>
    <inertial>
      <origin rpy="0 0 0" xyz="0 0 0"/>
      <mass value="0.2"/>
      <inertia ixx="0.0003" ixy="0" ixz="0" iyy="0.0003" iyz="0" izz="0.0003"/>
    </inertial>
  </link>
  <link name="finger_left">
    <visual>
      <geometry>
        <box size="0.1 0.02 0.1"/>
      </geometry>
      <origin rpy="0 0 0" xyz="0 0 0.05"/>
    </visual>
    <collision>
      <geometry>
        <box size="0.1 0.02 0.1"/>
      </geometry>
      <origin rpy="0 0 0" xyz="0 0 0.05"/>
    </collision>
    <inertial>
      <origin rpy="0 0 0" xyz="0 0 0.05"/>
      <mass value="0.05"/>
      <inertia ixx="0.00001" ixy="0" ixz="0" iyy="0.00001" iyz="0" izz="0.00001"/>
    </inertial>
  </link>
  <link name="finger_right">
    <visual>
      <geometry>
        <box size="0.1 0.02 0.1"/>
      </geometry>
      <origin rpy="0 0 0" xyz="0 0 0.05"/>
    </visual>
    <collision>
      <geometry>
        <box size="0.1 0.02 0.1"/>
      </geometry>
      <origin rpy="0 0 0" xyz="0 0 0.05"/>
    </collision>
    <inertial>
      <origin rpy="0 0 0" xyz="0 0 0.05"/>
      <mass value="0.05"/>
      <inertia ixx="0.00001" ixy="0" ixz="0" iyy="0.00001" iyz="0" izz="0.00001"/>
    </inertial>
  </link>
  <!-- joint 1 -->
  <joint name="joint1" type="revolute">
    <parent link="base_link"/>
    <child link="link1"/>
    <origin rpy="0 0 0" xyz="0 0 0.6"/>
    <axis xyz="0 0 1"/>
    <limit effort="1" lower="-3.14" upper="3.14" velocity="1"/>
  </joint>
  <!-- joint 2 -->
  <joint name="joint2" type="revolute">
    <parent link="link1"/>
    <child link="link2"/>
    <origin rpy="0 0 0" xyz="0 0 0.3"/>
    <axis xyz="0 1 0"/>
    <limit effort="1" lower="-3.14" upper="3.14" velocity="1"/>
  </joint>
  <!-- joint 3 -->
  <joint name="joint3" type="revolute">
    <parent link="link2"/>
    <child link="link3"/>
    <origin rpy="0 0 0" xyz="0 0 0.6"/>
    <axis xyz="0 1 0"/>
    <limit effort="1" lower="-3.14" upper="3.14" velocity="1"/>
  </joint>
  <!-- joint 4 -->
  <joint name="joint4" type="revolute">
    <parent link="link3"/>
    <child link="gripper_base"/>
    <origin rpy="0 0 0" xyz="0 0 0.65"/>
    <axis xyz="0 0 1"/>
    <limit effort="1" lower="-3.14" upper="3.14" velocity="1"/>
  </joint>
  <joint name="finger_left_joint" type="prismatic">
    <parent link="gripper_base"/>
    <child link="finger_left"/>
    <origin rpy="0 0 0" xyz="0 0.05 0.05"/>
    <axis xyz="0 -1 0"/>
    <limit effort="1" lower="0" upper="0.04" velocity="1"/>
  </joint>
  <joint name="finger_right_joint" type="prismatic">
    <parent link="gripper_base"/>
    <child link="finger_right"/>
    <origin rpy="0 0 0" xyz="0 -0.05 0.05"/>
    <axis xyz="0 1 0"/>
    <limit effort="1" lower="0" upper="0.04" velocity="1"/>
  </joint>
  <ros2_control name="FakeSystem" type="system">
    <hardware>
      <!-- By default, set up controllers for simulation. This won't work on real hardware -->
      <plugin>gz_ros2_control/GazeboSimSystem</plugin>
    </hardware>
    <joint name="joint1">
      <command_interface name="position"/>
      <state_interface name="position">
        <param name="initial_value">0</param>
      </state_interface>
      <state_interface name="velocity"/>
    </joint>
    <joint name="joint2">
      <command_interface name="position"/>
      <state_interface name="position">
        <param name="initial_value">0</param>
      </state_interface>
      <state_interface name="velocity"/>
    </joint>
    <joint name="joint3">
      <command_interface name="position"/>
      <state_interface name="position">
        <param name="initial_value">0</param>
      </state_interface>
      <state_interface name="velocity"/>
    </joint>
    <joint name="joint4">
      <command_interface name="position"/>
      <state_interface name="position">
        <param name="initial_value">0</param>
      </state_interface>
      <state_interface name="velocity"/>
    </joint>
    <joint name="finger_left_joint">
      <command_interface name="position"/>
      <state_interface name="position">
        <param name="initial_value">0</param>
      </state_interface>
      <state_interface name="velocity"/>
    </joint>
    <joint name="finger_right_joint">
      <command_interface name="position"/>
      <state_interface name="position">
        <param name="initial_value">0</param>
      </state_interface>
      <state_interface name="velocity"/>
    </joint>
  </ros2_control>
  <gazebo>
    <plugin filename="libgz_ros2_control-system.so" name="gz_ros2_control::GazeboSimROS2ControlPlugin">
      <parameters>/home/user/ros2_ws/install/myfirst_moveit_config/share/myfirst_moveit_config/config/ros2_controllers.yaml</parameters>
      <controller_manager_name>controller_manager</controller_manager_name>
    </plugin>
  </gazebo>
</robot>
